<mujoco model="lus2">
    <compiler angle="radian" meshdir="../meshes/"/>

    <default>
        <default class="lus2">
            <geom friction="0.5" margin="0.001"/>
            <joint type="hinge" damping="1" armature="0.1" frictionloss="0.1" limited="true"/>
            <motor ctrlrange="-200 200" />
            <default class="visual">
                <geom type="mesh" contype="0" conaffinity="0" group="2" material="dark"/>
            </default>
            <default class="collision">
                <geom group="0" type="capsule" mass="0" density="0" />
                <default class="foot">
                    <geom type="sphere" priority="1" solimp="0.015 1 0.031" condim="6"  friction="0.8 0.02 0.01" size="0.025" pos="0.019 0 -0.105" quat="1 0 0 0" rgba="0.189804 0.176471 0.129412 1" />
                </default>
            </default>
            <site size="0.001" rgba="0.5 0.5 0.5 0.3" group="4"/>
        </default>
    </default>


    <asset>
        <mesh name="pelvis" content_type="model/stl" file="pelvis.STL"/>
        <mesh name="left_hip_pitch_link" content_type="model/stl" file="left_hip_pitch_link.STL"/>
        <mesh name="left_hip_roll_link" content_type="model/stl" file="left_hip_roll_link.STL"/>
        <mesh name="left_hip_yaw_link" content_type="model/stl" file="left_hip_yaw_link.STL"/>
        <mesh name="left_knee_link" content_type="model/stl" file="left_knee_link.STL"/>
        <mesh name="left_ankle_pitch_link" content_type="model/stl" file="left_ankle_pitch_link.STL"/>
        <mesh name="left_ankle_roll_link" content_type="model/stl" file="left_ankle_roll_link.STL"/>
        <mesh name="right_hip_pitch_link" content_type="model/stl" file="right_hip_pitch_link.STL"/>
        <mesh name="right_hip_roll_link" content_type="model/stl" file="right_hip_roll_link.STL"/>
        <mesh name="right_hip_yaw_link" content_type="model/stl" file="right_hip_yaw_link.STL"/>
        <mesh name="right_knee_link" content_type="model/stl" file="right_knee_link.STL"/>
        <mesh name="right_ankle_pitch_link" content_type="model/stl" file="right_ankle_pitch_link.STL"/>
        <mesh name="right_ankle_roll_link" content_type="model/stl" file="right_ankle_roll_link.STL"/>
        <mesh name="torso_link" content_type="model/stl" file="torso_link.STL"/>
        <mesh name="head_link" content_type="model/stl" file="head_link.STL"/>
        <mesh name="left_shoulder_pitch_link" content_type="model/stl" file="left_shoulder_pitch_link.STL"/>
        <mesh name="left_shoulder_roll_link" content_type="model/stl" file="left_shoulder_roll_link.STL"/>
        <mesh name="left_shoulder_yaw_link" content_type="model/stl" file="left_shoulder_yaw_link.STL"/>
        <mesh name="left_elbow_link" content_type="model/stl" file="left_elbow_link.STL"/>
        <mesh name="left_wrist_yaw_link" content_type="model/stl" file="left_wrist_yaw_link.STL"/>
        <mesh name="left_wrist_pitch_link" content_type="model/stl" file="left_wrist_pitch_link.STL"/>
        <mesh name="left_wrist_roll_link" content_type="model/stl" file="left_wrist_roll_link.STL"/>
        <mesh name="right_shoulder_pitch_link" content_type="model/stl" file="right_shoulder_pitch_link.STL"/>
        <mesh name="right_shoulder_roll_link" content_type="model/stl" file="right_shoulder_roll_link.STL"/>
        <mesh name="right_shoulder_yaw_link" content_type="model/stl" file="right_shoulder_yaw_link.STL"/>
        <mesh name="right_elbow_link" content_type="model/stl" file="right_elbow_link.STL"/>
        <mesh name="right_wrist_yaw_link" content_type="model/stl" file="right_wrist_yaw_link.STL"/>
        <mesh name="right_wrist_pitch_link" content_type="model/stl" file="right_wrist_pitch_link.STL"/>
        <mesh name="right_wrist_roll_link" content_type="model/stl" file="right_wrist_roll_link.STL"/>


        <texture name="texplane" type="2d" builtin="checker" rgb1=".2 .3 .4" rgb2=".1 0.15 0.2" width="100" height="100"/>
        <material name="MatPlane" reflectance="0.5" texture="texplane" texrepeat="1 1" texuniform="true"/>
    </asset>


    <worldbody>
            <!-->
            <body name="anchor_point" pos="0 0 2">
            <site name="anchor_site" pos="0 0 0" size="0.01" />
            </body>
                <-->

            <geom name="floor" friction="1 .1 .1" pos="0 0 0" size="500 500 0.125" type="plane" material="MatPlane" condim="3" conaffinity="1" contype="1" group="2" rgba="0.8 0.9 0.8 1"></geom>                                                                                                                                                      

            <light cutoff="100" diffuse="1 1 1" dir="-0 0 -1.3" directional="true" exponent="1" pos="0 0 1.3" specular=".1 .1 .1" castshadow="false"/>  
            <body name="pelvis" pos="0 0 1.0" childclass="lus2">
                <inertial pos="-3.1659855E-03  0.0000000 -0.0930236E-01" quat="0.498303 0.499454 -0.500496 0.501741" mass="6.7964049" diaginertia="2.2011165e-02 3.9641975e-02 3.5762219e-02" />
                <joint name="floating_base_joint" type="free" limited="false" actuatorfrclimited="false"/>
                <site name='imu' size='0.01' pos='0.0 0 0.0'/>

                <!-- fill below content to finish urdf2mjcf -->


                <geom pos="0 0 0.1" quat="1 0 0 0" type="mesh" contype="0" conaffinity="0" group="1" density="0" rgba="0.752941 0.752941 0.752941 1" mesh="pelvis"/>
                <geom size="0.0572 0.09415" type="cylinder" rgba="0.752941 0.752941 0.752941 1"/>
                <body name="left_hip_pitch_link" pos="0 0.068 -0.056">
                    <inertial pos="-0.0201683 0.0822161 0" quat="0.704101 0.704101 0.0651255 0.0651255" mass="2.42773" diaginertia="0.00623422 0.00516186 0.00352913"/>
                    <joint name="left_hip_pitch_joint" pos="0 0 0" axis="0 1 0" range="-1.5 1.5" actuatorfrcrange="-380 380"/>
                    <geom type="mesh" contype="0" conaffinity="0" group="1" density="0" rgba="0.752941 0.752941 0.752941 1" mesh="left_hip_pitch_link"/>
                    <geom size="0.045 0.0117" pos="0 0.01 0" quat="0.707388 0.706825 0 0" type="cylinder" rgba="0.752941 0.752941 0.752941 1"/>
                    <body name="left_hip_roll_link" pos="0 0.092 0">
                        <inertial pos="-0.00231162 -0.00036364 -0.081422" quat="0.986446 -0.0128273 0.163575 0.00198067" mass="3.15516" diaginertia="0.0127869 0.0114832 0.00651926"/>
                        <joint name="left_hip_roll_joint" pos="0 0 0" axis="1 0 0" range="-0.25 2.8" actuatorfrcrange="-380 380"/>
                        <geom type="mesh" contype="0" conaffinity="0" group="1" density="0" rgba="0.752941 0.752941 0.752941 1" mesh="left_hip_roll_link"/>
                        <geom size="0.065 0.065" pos="-0.01 0 0" quat="0.707388 0 0.706825 0" type="cylinder" rgba="0.752941 0.752941 0.752941 1"/>
                        <body name="left_hip_yaw_link" pos="0 0 -0.1395">
                            <inertial pos="0.00642805 -0.00358464 -0.184496" quat="0.693667 -0.00118225 0.0183074 0.720062" mass="3.35223" diaginertia="0.0396254 0.0381203 0.0071533"/>
                            <joint name="left_hip_yaw_joint" pos="0 0 0" axis="0 0 1" range="-1.2 2.6" actuatorfrcrange="-380 380"/>
                            <geom type="mesh" contype="0" conaffinity="0" group="1" density="0" rgba="0.752941 0.752941 0.752941 1" mesh="left_hip_yaw_link"/>
                            <geom size="0.0708 0.071" type="cylinder" rgba="0.752941 0.752941 0.752941 1"/>
                            <body name="left_knee_link" pos="0 0 -0.26">
                                <inertial pos="0.00978041 -0.00121598 -0.110007" quat="0.690926 0.000275879 -0.0112168 0.722838" mass="5.38282" diaginertia="0.0720794 0.0710269 0.00814125"/>
                                <joint name="left_knee_joint" pos="0 0 0" axis="0 1 0" range="0 2.27" actuatorfrcrange="-380 380"/>
                                <geom type="mesh" contype="0" conaffinity="0" group="1" density="0" rgba="0.752941 0.752941 0.752941 1" mesh="left_knee_link"/>
                                <geom size="0.0545 0.0475 0.139" pos="0 0 -0.13" type="box" rgba="0.752941 0.752941 0.752941 1"/>
                                <body name="left_ankle_pitch_link" pos="0 0 -0.4">
                                    <inertial pos="-0.000310026 1.10617e-05 -0.0042516" quat="0.691176 0.691169 0.149264 -0.14927" mass="0.163759" diaginertia="5.58316e-05 5.50037e-05 2.3119e-05"/>
                                    <joint name="left_ankle_pitch_joint" pos="0 0 0" axis="0 1 0" range="-0.34 0.17" actuatorfrcrange="-200 200"/>
                                    <geom type="mesh" contype="0" conaffinity="0" group="1" density="0" rgba="0.898039 0.917647 0.929412 1" mesh="left_ankle_pitch_link"/>
                                    <geom size="0.009 0.016" quat="0.707388 0.706825 0 0" type="cylinder" rgba="0.898039 0.917647 0.929412 1"/>
                                    <body name="left_ankle_roll_link" pos="0 0 -0.01">
                                        <inertial pos="0.0178042 0 -0.022945" quat="0 0.734587 0 0.678514" mass="0.328402" diaginertia="0.00147826 0.00138491 0.000224893"/>
                                        <joint name="left_ankle_roll_joint" pos="0 0 0" axis="1 0 0" range="-0.26 0.26" actuatorfrcrange="-200 200"/>
                                        <geom type="mesh" contype="0" conaffinity="0" group="1" density="0" rgba="0.752941 0.752941 0.752941 1" mesh="left_ankle_roll_link"/>
                                        <geom size="0.1175 0.0365 0.00715" pos="0.025 0 -0.02585" type="box" rgba="0.752941 0.752941 0.752941 1"/>
                                    </body>
                                </body>
                            </body>
                        </body>
                    </body>
                </body>
                <body name="right_hip_pitch_link" pos="0 -0.068 -0.056">
                    <inertial pos="-0.0201683 -0.0822161 0" quat="0.704101 0.704101 -0.0651255 -0.0651255" mass="2.42773" diaginertia="0.00623422 0.00516186 0.00352913"/>
                    <joint name="right_hip_pitch_joint" pos="0 0 0" axis="0 1 0" range="-1.5 1.5" actuatorfrcrange="-380 380"/>
                    <geom type="mesh" contype="0" conaffinity="0" group="1" density="0" rgba="0.752941 0.752941 0.752941 1" mesh="right_hip_pitch_link"/>
                    <geom size="0.045 0.0117" pos="0 -0.01 0" quat="0.707388 0.706825 0 0" type="cylinder" rgba="0.752941 0.752941 0.752941 1"/>
                    <body name="right_hip_roll_link" pos="0 -0.092 0">
                        <inertial pos="-0.00231164 0.000363676 -0.0814221" quat="0.986446 0.0128271 0.163575 -0.00197953" mass="3.15516" diaginertia="0.0127868 0.0114832 0.00651926"/>
                        <joint name="right_hip_roll_joint" pos="0 0 0" axis="1 0 0" range="-2.8 0.25" actuatorfrcrange="-380 380"/>
                        <geom type="mesh" contype="0" conaffinity="0" group="1" density="0" rgba="0.752941 0.752941 0.752941 1" mesh="right_hip_roll_link"/>
                        <geom size="0.065 0.065" pos="-0.01 0 0" quat="0.707388 0 0.706825 0" type="cylinder" rgba="0.752941 0.752941 0.752941 1"/>
                        <body name="right_hip_yaw_link" pos="0 0 -0.1395">
                            <inertial pos="0.00642805 0.00358464 -0.184496" quat="0.720062 0.0183074 -0.00118225 0.693667" mass="3.35223" diaginertia="0.0396254 0.0381203 0.0071533"/>
                            <joint name="right_hip_yaw_joint" pos="0 0 0" axis="0 0 1" range="-2.6 1.2" actuatorfrcrange="-380 380"/>
                            <geom type="mesh" contype="0" conaffinity="0" group="1" density="0" rgba="0.752941 0.752941 0.752941 1" mesh="right_hip_yaw_link"/>
                            <geom size="0.0708 0.071" type="cylinder" rgba="0.752941 0.752941 0.752941 1"/>
                            <body name="right_knee_link" pos="0 0 -0.26">
                                <inertial pos="0.00978041 0.00121598 -0.110007" quat="0.722838 -0.0112168 0.00027589 0.690926" mass="5.38282" diaginertia="0.0720794 0.0710269 0.00814125"/>
                                <joint name="right_knee_joint" pos="0 0 0" axis="0 1 0" range="0 2.27" actuatorfrcrange="-380 380"/>
                                <geom type="mesh" contype="0" conaffinity="0" group="1" density="0" rgba="0.752941 0.752941 0.752941 1" mesh="right_knee_link"/>
                                <geom size="0.0545 0.0475 0.139" pos="0 0 -0.13" type="box" rgba="0.752941 0.752941 0.752941 1"/>
                                <body name="right_ankle_pitch_link" pos="0 0 -0.4">
                                    <inertial pos="-0.000310026 1.10617e-05 -0.0042516" quat="0.691176 0.691169 0.149264 -0.14927" mass="0.163759" diaginertia="5.58316e-05 5.50037e-05 2.3119e-05"/>
                                    <joint name="right_ankle_pitch_joint" pos="0 0 0" axis="0 1 0" range="-0.34 0.17" actuatorfrcrange="-200 200"/>
                                    <geom type="mesh" contype="0" conaffinity="0" group="1" density="0" rgba="0.898039 0.917647 0.929412 1" mesh="right_ankle_pitch_link"/>
                                    <geom size="0.009 0.016" quat="0.707388 0.706825 0 0" type="cylinder" rgba="0.898039 0.917647 0.929412 1"/>
                                    <body name="right_ankle_roll_link" pos="0 0 -0.01">
                                        <inertial pos="0.0178042 0 -0.022945" quat="0 0.734587 0 0.678514" mass="0.328402" diaginertia="0.00147826 0.00138491 0.000224893"/>
                                        <joint name="right_ankle_roll_joint" pos="0 0 0" axis="1 0 0" range="-0.26 0.26" actuatorfrcrange="-200 200"/>
                                        <geom type="mesh" contype="0" conaffinity="0" group="1" density="0" rgba="0.752941 0.752941 0.752941 1" mesh="right_ankle_roll_link"/>
                                        <geom size="0.1175 0.0365 0.00715" pos="0.025 0 -0.02585" type="box" rgba="0.752941 0.752941 0.752941 1"/>
                                    </body>
                                </body>
                            </body>
                        </body>
                    </body>
                </body>
                <body name="torso_link" pos="0 0 0.1">

                    <site name="torso_site1" pos="-0.1 0.1 0.3" />
                    <site name="torso_site2" pos="-0.1 -0.1 0.3" />

                    <inertial pos="-0.00142182 0.000240176 0.254143" quat="0.999922 -0.00157977 -0.0120569 0.00275247" mass="11.5909" diaginertia="0.204443 0.180554 0.0681115"/>
                    <joint name="torso_joint" pos="0 0 0" axis="0 0 1" range="-3 3" actuatorfrcrange="-380 380"/>
                    <geom type="mesh" contype="0" conaffinity="0" group="1" density="0" rgba="0.752941 0.752941 0.752941 1" mesh="torso_link"/>
                    <geom size="0.1025 0.089 0.123" pos="0.0065 0 0.21" type="box" rgba="0.752941 0.752941 0.752941 1"/>
                    <geom pos="0 0 0.3875" quat="1 0 0 0" type="mesh" contype="0" conaffinity="0" group="1" density="0" rgba="0.752941 0.752941 0.752941 1" mesh="head_link"/>
                    <geom size="0.08" pos="0 0 0.4975" rgba="0.752941 0.752941 0.752941 1"/>
                    <body name="left_shoulder_pitch_link" pos="0 0.12095 0.29712" quat="0.996195 -0.0871543 0 0">
                        <inertial pos="-0.0254614 0.0534578 -5.75839e-07" quat="0.702171 0.702182 0.0833408 0.0833656" mass="0.173115" diaginertia="0.000197536 0.000152139 9.0815e-05"/>
                        <joint name="left_shoulder_pitch_joint" pos="0 0 0" axis="0 1 0" range="-3 3" actuatorfrcrange="-100 100"/>
                        <geom type="mesh" contype="0" conaffinity="0" group="1" density="0" rgba="0.752941 0.752941 0.752941 1" mesh="left_shoulder_pitch_link"/>
                        <geom size="0.0244 0.009" pos="0 0.01 0" quat="0.707388 0.706825 0 0" type="cylinder" rgba="0.752941 0.752941 0.752941 1"/>
                        <body name="left_shoulder_roll_link" pos="0 0.0695 0" quat="0.996195 0.0871543 0 0">
                            <inertial pos="0.00112286 -4.52209e-05 -0.067975" quat="0.999793 0.00155022 -0.0201616 0.00208659" mass="0.364745" diaginertia="0.000924429 0.000788402 0.000365403"/>
                            <joint name="left_shoulder_roll_joint" pos="0 0 0" axis="1 0 0" range="-0.12 2.3" actuatorfrcrange="-100 100"/>
                            <geom type="mesh" contype="0" conaffinity="0" group="1" density="0" rgba="0.752941 0.752941 0.752941 1" mesh="left_shoulder_roll_link"/>
                            <geom size="0.0447 0.05" quat="0.707388 0 0.706825 0" type="cylinder" rgba="0.752941 0.752941 0.752941 1"/>
                            <body name="left_shoulder_yaw_link" pos="0 0 -0.13">
                                <inertial pos="-0.00081064 -0.00072673 -0.105837" quat="0.693666 -0.00598888 0.000250759 0.720272" mass="1.12432" diaginertia="0.00391994 0.00383464 0.000723036"/>
                                <joint name="left_shoulder_yaw_joint" pos="0 0 0" axis="0 0 1" range="-1.9 1.9" actuatorfrcrange="-100 100"/>
                                <geom type="mesh" contype="0" conaffinity="0" group="1" density="0" rgba="0.752941 0.752941 0.752941 1" mesh="left_shoulder_yaw_link"/>
                                <geom size="0.03968 0.07" type="cylinder" rgba="0.752941 0.752941 0.752941 1"/>
                                <body name="left_elbow_link" pos="0 0 -0.14" quat="0.707388 0 -0.706825 0">
                                    <inertial pos="-0.00152308 -0.00155026 -0.0668646" quat="0.992371 -0.0434666 0.063854 0.0960856" mass="0.593099" diaginertia="0.000843319 0.0008126 0.000468311"/>
                                    <joint name="left_elbow_joint" pos="0 0 0" axis="0 1 0" range="-0.83 1.57" actuatorfrcrange="-100 100"/>
                                    <geom type="mesh" contype="0" conaffinity="0" group="1" density="0" rgba="0.752941 0.752941 0.752941 1" mesh="left_elbow_link"/>
                                    <geom size="0.043 0.0395" quat="0.707388 0.706825 0 0" type="cylinder" rgba="0.752941 0.752941 0.752941 1"/>
                                    <body name="left_wrist_yaw_link" pos="0 0 -0.0955">
                                        <inertial pos="0.00020795 -0.00477305 -0.0659639" quat="0.709413 -0.101584 -0.105057 0.689476" mass="0.36396" diaginertia="0.000192068 0.000133146 0.000131356"/>
                                        <joint name="left_wrist_yaw_joint" pos="0 0 0" axis="0 0 1" range="-2.3 2.3" actuatorfrcrange="-20 20"/>
                                        <geom type="mesh" contype="0" conaffinity="0" group="1" density="0" rgba="0.752941 0.752941 0.752941 1" mesh="left_wrist_yaw_link"/>
                                        <geom size="0.035 0.035" pos="0 0 0.01" type="cylinder" rgba="0.752941 0.752941 0.752941 1"/>
                                        <body name="left_wrist_pitch_link" pos="0 0 -0.0645">
                                            <inertial pos="-0.00480941 -0.00060521 -0.0582503" quat="0.99617 -0.0667976 -0.0505555 -0.0250494" mass="0.471098" diaginertia="0.000388022 0.000316156 0.000229722"/>
                                            <joint name="left_wrist_pitch_joint" pos="0 0 0" axis="0 1 0" range="-1.2 1.2" actuatorfrcrange="-20 20"/>
                                            <geom type="mesh" contype="0" conaffinity="0" group="1" density="0" rgba="0.752941 0.752941 0.752941 1" mesh="left_wrist_pitch_link"/>
                                            <geom size="0.032 0.032" quat="0.707388 0.706825 0 0" type="cylinder" rgba="0.752941 0.752941 0.752941 1"/>
                                            <body name="left_wrist_roll_link" pos="0 0 -0.068">
                                                <inertial pos="0.0191604 -1.17e-06 -0.023948" quat="0.683304 -0.181921 -0.181921 0.683304" mass="0.0380932" diaginertia="2.008e-05 1.90086e-05 7.00137e-06"/>
                                                <joint name="left_wrist_roll_joint" pos="0 0 0" axis="1 0 0" range="-1.2 1.2" actuatorfrcrange="-20 20"/>
                                                <geom type="mesh" contype="0" conaffinity="0" group="1" density="0" rgba="0.752941 0.752941 0.752941 1" mesh="left_wrist_roll_link"/>
                                                <geom size="0.035 0.027" quat="0.707388 0 0.706825 0" type="cylinder" rgba="0.752941 0.752941 0.752941 1"/>
                                            </body>
                                        </body>
                                    </body>
                                </body>
                            </body>
                        </body>
                    </body>
                    <body name="right_shoulder_pitch_link" pos="0 -0.12095 0.29712" quat="0.996195 0.0871543 0 0">
                        <inertial pos="-0.0254614 -0.0534578 6.93877e-07" quat="0.702166 0.702188 -0.0833419 -0.0833635" mass="0.173115" diaginertia="0.00019754 0.00015214 9.08183e-05"/>
                        <joint name="right_shoulder_pitch_joint" pos="0 0 0" axis="0 1 0" range="-3 3" actuatorfrcrange="-100 100"/>
                        <geom type="mesh" contype="0" conaffinity="0" group="1" density="0" rgba="0.752941 0.752941 0.752941 1" mesh="right_shoulder_pitch_link"/>
                        <geom size="0.0244 0.009" pos="0 -0.01 0" quat="0.707388 0.706825 0 0" type="cylinder" rgba="0.752941 0.752941 0.752941 1"/>
                        <body name="right_shoulder_roll_link" pos="0 -0.0695 0" quat="0.996195 -0.0871543 0 0">
                            <inertial pos="0.00112483 5.05515e-05 -0.0679738" quat="0.999794 -0.0015408 -0.0201519 -0.00208832" mass="0.364802" diaginertia="0.00092448 0.000788455 0.000365414"/>
                            <joint name="right_shoulder_roll_joint" pos="0 0 0" axis="1 0 0" range="-2.3 0.12" actuatorfrcrange="-100 100"/>
                            <geom type="mesh" contype="0" conaffinity="0" group="1" density="0" rgba="0.752941 0.752941 0.752941 1" mesh="right_shoulder_roll_link"/>
                            <geom size="0.0447 0.05" quat="0.707388 0 0.706825 0" type="cylinder" rgba="0.752941 0.752941 0.752941 1"/>
                            <body name="right_shoulder_yaw_link" pos="0 0 -0.13">
                                <inertial pos="-0.00081059 0.00072671 -0.105749" quat="0.720253 0.0003316 -0.00594525 0.693686" mass="1.12432" diaginertia="0.00391319 0.00382787 0.000723043"/>
                                <joint name="right_shoulder_yaw_joint" pos="0 0 0" axis="0 0 1" range="-1.9 1.9" actuatorfrcrange="-100 100"/>
                                <geom type="mesh" contype="0" conaffinity="0" group="1" density="0" rgba="0.752941 0.752941 0.752941 1" mesh="right_shoulder_yaw_link"/>
                                <geom size="0.03968 0.07" type="cylinder" rgba="0.752941 0.752941 0.752941 1"/>
                                <body name="right_elbow_link" pos="0 0 -0.14" quat="0.707388 0 -0.706825 0">
                                    <inertial pos="-0.00139017 0.0014914 -0.066865" quat="0.992139 0.0427742 0.0625601 -0.0995795" mass="0.593091" diaginertia="0.00084363 0.000812263 0.000468977"/>
                                    <joint name="right_elbow_joint" pos="0 0 0" axis="0 1 0" range="-0.83 1.57" actuatorfrcrange="-100 100"/>
                                    <geom type="mesh" contype="0" conaffinity="0" group="1" density="0" rgba="0.752941 0.752941 0.752941 1" mesh="right_elbow_link"/>
                                    <geom size="0.043 0.0395" quat="0.707388 0.706825 0 0" type="cylinder" rgba="0.752941 0.752941 0.752941 1"/>
                                    <body name="right_wrist_yaw_link" pos="0 0 -0.0955">
                                        <inertial pos="-0.00020795 0.00477305 -0.0659639" quat="0.709413 0.101584 0.105057 0.689476" mass="0.36396" diaginertia="0.000192068 0.000133146 0.000131356"/>
                                        <joint name="right_wrist_yaw_joint" pos="0 0 0" axis="0 0 1" range="-2.3 2.3" actuatorfrcrange="-20 20"/>
                                        <geom type="mesh" contype="0" conaffinity="0" group="1" density="0" rgba="0.752941 0.752941 0.752941 1" mesh="right_wrist_yaw_link"/>
                                        <geom size="0.035 0.035" pos="0 0 0.01" type="cylinder" rgba="0.752941 0.752941 0.752941 1"/>
                                        <body name="right_wrist_pitch_link" pos="0 0 -0.0645">
                                            <inertial pos="-0.0048094 0.00036052 -0.058458" quat="0.996274 0.0735022 -0.0442922 0.00858283" mass="0.471098" diaginertia="0.000388936 0.000316854 0.00023094"/>
                                            <joint name="right_wrist_pitch_joint" pos="0 0 0" axis="0 1 0" range="-1.2 1.2" actuatorfrcrange="-20 20"/>
                                            <geom type="mesh" contype="0" conaffinity="0" group="1" density="0" rgba="0.752941 0.752941 0.752941 1" mesh="right_wrist_pitch_link"/>
                                            <geom size="0.032 0.032" quat="0.707388 0.706825 0 0" type="cylinder" rgba="0.752941 0.752941 0.752941 1"/>
                                            <body name="right_wrist_roll_link" pos="0 0 -0.068">
                                                <inertial pos="0.0191604 -1.17e-06 -0.023948" quat="0.683304 -0.181921 -0.181921 0.683304" mass="0.0380932" diaginertia="2.008e-05 1.90086e-05 7.00137e-06"/>
                                                <joint name="right_wrist_roll_joint" pos="0 0 0" axis="1 0 0" range="-1.2 1.2" actuatorfrcrange="-20 20"/>
                                                <geom type="mesh" contype="0" conaffinity="0" group="1" density="0" rgba="0.752941 0.752941 0.752941 1" mesh="right_wrist_roll_link"/>
                                                <geom size="0.035 0.027" quat="0.707388 0 0.706825 0" type="cylinder" rgba="0.752941 0.752941 0.752941 1"/>
                                            </body>
                                        </body>
                                    </body>
                                </body>
                            </body>
                        </body>
                    </body>
                </body>
                <!-- fill above segment -->
            </body>
        </worldbody>


        <actuator>
            <motor name="left_hip_pitch_joint" joint="left_hip_pitch_joint" gear="1" ctrllimited="true" ctrlrange="-380 380"/>
            <motor name="left_hip_roll_joint" joint="left_hip_roll_joint" gear="1" ctrllimited="true" ctrlrange="-380 380"/>
            <motor name="left_hip_yaw_joint" joint="left_hip_yaw_joint" gear="1" ctrllimited="true" ctrlrange="-380 380" />
            <motor name="left_knee_joint" joint="left_knee_joint" gear="1" ctrllimited="true" ctrlrange="-380 380"/>
            <motor name="left_ankle_pitch_joint" joint="left_ankle_pitch_joint" gear="1" ctrllimited="true" ctrlrange="-380 380"/>
            <motor name="left_ankle_roll_joint" joint="left_ankle_roll_joint" gear="1" ctrllimited="true" ctrlrange="-380 380"/>

            <motor name="right_hip_pitch_joint" joint="right_hip_pitch_joint" gear="1" ctrllimited="true" ctrlrange="-380 380"/>
            <motor name="right_hip_roll_joint" joint="right_hip_roll_joint" gear="1" ctrllimited="true" ctrlrange="-380 380"/>
            <motor name="right_hip_yaw_joint" joint="right_hip_yaw_joint" gear="1" ctrllimited="true" ctrlrange="-380 380"/>
            <motor name="right_knee_joint" joint="right_knee_joint" gear="1" ctrllimited="true" ctrlrange="-380 380" />
            <motor name="right_ankle_pitch_joint" joint="right_ankle_pitch_joint" gear="1" ctrllimited="true" ctrlrange="-380 380" />
            <motor name="right_ankle_roll_joint" joint="right_ankle_roll_joint" gear="1" ctrllimited="true" ctrlrange="-380 380" />

            <motor name="torso_joint" joint="torso_joint" gear="1" ctrllimited="true" ctrlrange="-380 380" /> 

            <motor name="left_shoulder_pitch_joint" joint="left_shoulder_pitch_joint" gear="1" ctrllimited="true" ctrlrange="-380 380" />
            <motor name="left_shoulder_roll_joint" joint="left_shoulder_roll_joint" gear="1" ctrllimited="true" ctrlrange="-380 380" />
            <motor name="left_shoulder_yaw_joint" joint="left_shoulder_yaw_joint" gear="1" ctrllimited="true" ctrlrange="-380 380" />
            <motor name="left_elbow_joint" joint="left_elbow_joint" gear="1" ctrllimited="true" ctrlrange="-380 380" />
            <motor name="left_wrist_yaw_joint" joint="left_wrist_yaw_joint" gear="1" ctrllimited="true" ctrlrange="-380 380" />
            <motor name="left_wrist_pitch_joint" joint="left_wrist_pitch_joint" gear="1" ctrllimited="true" ctrlrange="-380 380" />
            <motor name="left_wrist_roll_joint" joint="left_wrist_roll_joint" gear="1" ctrllimited="true" ctrlrange="-380 380" />

            <motor name="right_shoulder_pitch_joint" joint="right_shoulder_pitch_joint" gear="1" ctrllimited="true" ctrlrange="-380 380" />
            <motor name="right_shoulder_roll_joint" joint="right_shoulder_roll_joint" gear="1" ctrllimited="true" ctrlrange="-380 380" />
            <motor name="right_shoulder_yaw_joint" joint="right_shoulder_yaw_joint" gear="1" ctrllimited="true" ctrlrange="-380 380" />
            <motor name="right_elbow_joint" joint="right_elbow_joint" gear="1" ctrllimited="true" ctrlrange="-380 380" />
            <motor name="right_wrist_yaw_joint" joint="right_wrist_yaw_joint" gear="1" ctrllimited="true" ctrlrange="-380 380" />
            <motor name="right_wrist_pitch_joint" joint="right_wrist_pitch_joint" gear="1" ctrllimited="true" ctrlrange="-380 380" />
            <motor name="right_wrist_roll_joint" joint="right_wrist_roll_joint" gear="1" ctrllimited="true" ctrlrange="-380 380" />

        </actuator>

        <sensor>
            <framequat     name='orientation' objtype='site' noise='0.001' objname='imu'/>
            <framepos     name='position' objtype='site' noise='0.001' objname='imu'/>
            <gyro          name='angular-velocity'    site='imu' noise='0.005' cutoff='34.9'/>
            <velocimeter   name='linear-velocity'     site='imu' noise='0.001' cutoff='30'/>
            <accelerometer name='linear-acceleration' site='imu' noise='0.005' cutoff='157'/>
            <magnetometer  name='magnetometer'        site='imu'/>
        </sensor>


        <!-->
            <tendon>
            <spatial name="hang_string1" stiffness="8000" damping="50">
            <site site="anchor_site"/>
            <site site="torso_site1"/>
            </spatial>
            </tendon>

            <tendon>
            <spatial name="hang_string2" stiffness="8000" damping="50">
            <site site="anchor_site"/>
            <site site="torso_site2"/>
            </spatial>
            </tendon>
        <-->


        </mujoco>
